Workbook

Sheet Read me
B2: RegPilot QA test cases
B3: Written from everything built and learned so far: web app, AI extraction, review screen, extension and Montaji behaviour.
B5: How to use | C5: Work through the "Test cases" sheet top to bottom, P1 first. For each case set Result (Pass / Fail / Blocked), write what you saw in "Tester notes", and put the fix reference or date when we resolve it. Send me the sheet or just the failed rows and we fix on the go.
B6: Yellow cells | C6: These are the only cells you edit: Result, Tester notes, Bug / fix reference and Date tested (Test cases), the value columns (Data audit).
B7: Priority | C7: P1 = must pass before real use. P2 = important. P3 = edge case or nice to have.
B8: Result values | C8: Not run (default) | Pass | Fail | Blocked (cannot test yet, e.g. portal down or document missing).
B9: Documents | C9: The "Documents / data needed" column and the "Document pack" sheet say which real document sets to collect. One set can serve many cases.
B10: Data audit | C10: After any end-to-end run, use the "Data audit" sheet to compare RegPilot values with what is on Montaji, field by field. Copy a block for each product.
B11: Known limits | C11: The "Known limits" sheet lists things we already know are missing, so you do not log them as bugs (log them only if they behave worse than described).
B12: Safety | C12: Test only on DM STACEY ACCOUNT. Never press Submit. Delete your test drafts afterwards. Do not click on Montaji while a fill is running. After every extension reload refresh both the RegPilot and the Montaji tabs.
B13: Example row | C13: ID EXT-01 | Scenario "Complete set, single variant" | Result: Fail | Notes: "Barcode last digit wrong: label 6294019034727, extracted 6294019034723" | Fix ref: "Extraction prompt, 17 Oct".

Sheet Summary
A1: Progress summary
A2: Counts update by themselves from the Result column on the Test cases sheet.
A4: Area | B4: Cases | C4: Pass | D4: Fail | E4: Blocked | F4: Not run | G4: % done | H4: P1 cases | I4: P1 passed
A5: Accounts & companies | B5: =COUNTIFS('Test cases'!$B$2:$B$182,$A5) | C5: =COUNTIFS('Test cases'!$B$2:$B$182,$A5,'Test cases'!$H$2:$H$182,"Pass") | D5: =COUNTIFS('Test cases'!$B$2:$B$182,$A5,'Test cases'!$H$2:$H$182,"Fail") | E5: =COUNTIFS('Test cases'!$B$2:$B$182,$A5,'Test cases'!$H$2:$H$182,"Blocked") | F5: =COUNTIFS('Test cases'!$B$2:$B$182,$A5,'Test cases'!$H$2:$H$182,"Not run") | G5: =IF(B5=0,0,(C5+D5+E5)/B5) | H5: =COUNTIFS('Test cases'!$B$2:$B$182,$A5,'Test cases'!$C$2:$C$182,"P1") | I5: =COUNTIFS('Test cases'!$B$2:$B$182,$A5,'Test cases'!$C$2:$C$182,"P1",'Test cases'!$H$2:$H$182,"Pass")
A6: Product creation & documents | B6: =COUNTIFS('Test cases'!$B$2:$B$182,$A6) | C6: =COUNTIFS('Test cases'!$B$2:$B$182,$A6,'Test cases'!$H$2:$H$182,"Pass") | D6: =COUNTIFS('Test cases'!$B$2:$B$182,$A6,'Test cases'!$H$2:$H$182,"Fail") | E6: =COUNTIFS('Test cases'!$B$2:$B$182,$A6,'Test cases'!$H$2:$H$182,"Blocked") | F6: =COUNTIFS('Test cases'!$B$2:$B$182,$A6,'Test cases'!$H$2:$H$182,"Not run") | G6: =IF(B6=0,0,(C6+D6+E6)/B6) | H6: =COUNTIFS('Test cases'!$B$2:$B$182,$A6,'Test cases'!$C$2:$C$182,"P1") | I6: =COUNTIFS('Test cases'!$B$2:$B$182,$A6,'Test cases'!$C$2:$C$182,"P1",'Test cases'!$H$2:$H$182,"Pass")
A7: AI extraction accuracy (real documents) | B7: =COUNTIFS('Test cases'!$B$2:$B$182,$A7) | C7: =COUNTIFS('Test cases'!$B$2:$B$182,$A7,'Test cases'!$H$2:$H$182,"Pass") | D7: =COUNTIFS('Test cases'!$B$2:$B$182,$A7,'Test cases'!$H$2:$H$182,"Fail") | E7: =COUNTIFS('Test cases'!$B$2:$B$182,$A7,'Test cases'!$H$2:$H$182,"Blocked") | F7: =COUNTIFS('Test cases'!$B$2:$B$182,$A7,'Test cases'!$H$2:$H$182,"Not run") | G7: =IF(B7=0,0,(C7+D7+E7)/B7) | H7: =COUNTIFS('Test cases'!$B$2:$B$182,$A7,'Test cases'!$C$2:$C$182,"P1") | I7: =COUNTIFS('Test cases'!$B$2:$B$182,$A7,'Test cases'!$C$2:$C$182,"P1",'Test cases'!$H$2:$H$182,"Pass")
A8: Review & edit screen | B8: =COUNTIFS('Test cases'!$B$2:$B$182,$A8) | C8: =COUNTIFS('Test cases'!$B$2:$B$182,$A8,'Test cases'!$H$2:$H$182,"Pass") | D8: =COUNTIFS('Test cases'!$B$2:$B$182,$A8,'Test cases'!$H$2:$H$182,"Fail") | E8: =COUNTIFS('Test cases'!$B$2:$B$182,$A8,'Test cases'!$H$2:$H$182,"Blocked") | F8: =COUNTIFS('Test cases'!$B$2:$B$182,$A8,'Test cases'!$H$2:$H$182,"Not run") | G8: =IF(B8=0,0,(C8+D8+E8)/B8) | H8: =COUNTIFS('Test cases'!$B$2:$B$182,$A8,'Test cases'!$C$2:$C$182,"P1") | I8: =COUNTIFS('Test cases'!$B$2:$B$182,$A8,'Test cases'!$C$2:$C$182,"P1",'Test cases'!$H$2:$H$182,"Pass")
A9: Document warnings (red box above the review form) | B9: =COUNTIFS('Test cases'!$B$2:$B$182,$A9) | C9: =COUNTIFS('Test cases'!$B$2:$B$182,$A9,'Test cases'!$H$2:$H$182,"Pass") | D9: =COUNTIFS('Test cases'!$B$2:$B$182,$A9,'Test cases'!$H$2:$H$182,"Fail") | E9: =COUNTIFS('Test cases'!$B$2:$B$182,$A9,'Test cases'!$H$2:$H$182,"Blocked") | F9: =COUNTIFS('Test cases'!$B$2:$B$182,$A9,'Test cases'!$H$2:$H$182,"Not run") | G9: =IF(B9=0,0,(C9+D9+E9)/B9) | H9: =COUNTIFS('Test cases'!$B$2:$B$182,$A9,'Test cases'!$C$2:$C$182,"P1") | I9: =COUNTIFS('Test cases'!$B$2:$B$182,$A9,'Test cases'!$C$2:$C$182,"P1",'Test cases'!$H$2:$H$182,"Pass")
A10: Dashboard table | B10: =COUNTIFS('Test cases'!$B$2:$B$182,$A10) | C10: =COUNTIFS('Test cases'!$B$2:$B$182,$A10,'Test cases'!$H$2:$H$182,"Pass") | D10: =COUNTIFS('Test cases'!$B$2:$B$182,$A10,'Test cases'!$H$2:$H$182,"Fail") | E10: =COUNTIFS('Test cases'!$B$2:$B$182,$A10,'Test cases'!$H$2:$H$182,"Blocked") | F10: =COUNTIFS('Test cases'!$B$2:$B$182,$A10,'Test cases'!$H$2:$H$182,"Not run") | G10: =IF(B10=0,0,(C10+D10+E10)/B10) | H10: =COUNTIFS('Test cases'!$B$2:$B$182,$A10,'Test cases'!$C$2:$C$182,"P1") | I10: =COUNTIFS('Test cases'!$B$2:$B$182,$A10,'Test cases'!$C$2:$C$182,"P1",'Test cases'!$H$2:$H$182,"Pass")
A11: Send to extension | B11: =COUNTIFS('Test cases'!$B$2:$B$182,$A11) | C11: =COUNTIFS('Test cases'!$B$2:$B$182,$A11,'Test cases'!$H$2:$H$182,"Pass") | D11: =COUNTIFS('Test cases'!$B$2:$B$182,$A11,'Test cases'!$H$2:$H$182,"Fail") | E11: =COUNTIFS('Test cases'!$B$2:$B$182,$A11,'Test cases'!$H$2:$H$182,"Blocked") | F11: =COUNTIFS('Test cases'!$B$2:$B$182,$A11,'Test cases'!$H$2:$H$182,"Not run") | G11: =IF(B11=0,0,(C11+D11+E11)/B11) | H11: =COUNTIFS('Test cases'!$B$2:$B$182,$A11,'Test cases'!$C$2:$C$182,"P1") | I11: =COUNTIFS('Test cases'!$B$2:$B$182,$A11,'Test cases'!$C$2:$C$182,"P1",'Test cases'!$H$2:$H$182,"Pass")
A12: Montaji panel (the floating box) | B12: =COUNTIFS('Test cases'!$B$2:$B$182,$A12) | C12: =COUNTIFS('Test cases'!$B$2:$B$182,$A12,'Test cases'!$H$2:$H$182,"Pass") | D12: =COUNTIFS('Test cases'!$B$2:$B$182,$A12,'Test cases'!$H$2:$H$182,"Fail") | E12: =COUNTIFS('Test cases'!$B$2:$B$182,$A12,'Test cases'!$H$2:$H$182,"Blocked") | F12: =COUNTIFS('Test cases'!$B$2:$B$182,$A12,'Test cases'!$H$2:$H$182,"Not run") | G12: =IF(B12=0,0,(C12+D12+E12)/B12) | H12: =COUNTIFS('Test cases'!$B$2:$B$182,$A12,'Test cases'!$C$2:$C$182,"P1") | I12: =COUNTIFS('Test cases'!$B$2:$B$182,$A12,'Test cases'!$C$2:$C$182,"P1",'Test cases'!$H$2:$H$182,"Pass")
A13: Montaji Step 1-2: company & product base | B13: =COUNTIFS('Test cases'!$B$2:$B$182,$A13) | C13: =COUNTIFS('Test cases'!$B$2:$B$182,$A13,'Test cases'!$H$2:$H$182,"Pass") | D13: =COUNTIFS('Test cases'!$B$2:$B$182,$A13,'Test cases'!$H$2:$H$182,"Fail") | E13: =COUNTIFS('Test cases'!$B$2:$B$182,$A13,'Test cases'!$H$2:$H$182,"Blocked") | F13: =COUNTIFS('Test cases'!$B$2:$B$182,$A13,'Test cases'!$H$2:$H$182,"Not run") | G13: =IF(B13=0,0,(C13+D13+E13)/B13) | H13: =COUNTIFS('Test cases'!$B$2:$B$182,$A13,'Test cases'!$C$2:$C$182,"P1") | I13: =COUNTIFS('Test cases'!$B$2:$B$182,$A13,'Test cases'!$C$2:$C$182,"P1",'Test cases'!$H$2:$H$182,"Pass")
A14: Montaji Step 3: attachments | B14: =COUNTIFS('Test cases'!$B$2:$B$182,$A14) | C14: =COUNTIFS('Test cases'!$B$2:$B$182,$A14,'Test cases'!$H$2:$H$182,"Pass") | D14: =COUNTIFS('Test cases'!$B$2:$B$182,$A14,'Test cases'!$H$2:$H$182,"Fail") | E14: =COUNTIFS('Test cases'!$B$2:$B$182,$A14,'Test cases'!$H$2:$H$182,"Blocked") | F14: =COUNTIFS('Test cases'!$B$2:$B$182,$A14,'Test cases'!$H$2:$H$182,"Not run") | G14: =IF(B14=0,0,(C14+D14+E14)/B14) | H14: =COUNTIFS('Test cases'!$B$2:$B$182,$A14,'Test cases'!$C$2:$C$182,"P1") | I14: =COUNTIFS('Test cases'!$B$2:$B$182,$A14,'Test cases'!$C$2:$C$182,"P1",'Test cases'!$H$2:$H$182,"Pass")
A15: Montaji Step 4: variants | B15: =COUNTIFS('Test cases'!$B$2:$B$182,$A15) | C15: =COUNTIFS('Test cases'!$B$2:$B$182,$A15,'Test cases'!$H$2:$H$182,"Pass") | D15: =COUNTIFS('Test cases'!$B$2:$B$182,$A15,'Test cases'!$H$2:$H$182,"Fail") | E15: =COUNTIFS('Test cases'!$B$2:$B$182,$A15,'Test cases'!$H$2:$H$182,"Blocked") | F15: =COUNTIFS('Test cases'!$B$2:$B$182,$A15,'Test cases'!$H$2:$H$182,"Not run") | G15: =IF(B15=0,0,(C15+D15+E15)/B15) | H15: =COUNTIFS('Test cases'!$B$2:$B$182,$A15,'Test cases'!$C$2:$C$182,"P1") | I15: =COUNTIFS('Test cases'!$B$2:$B$182,$A15,'Test cases'!$C$2:$C$182,"P1",'Test cases'!$H$2:$H$182,"Pass")
A16: Ingredients (Excel import and entry) | B16: =COUNTIFS('Test cases'!$B$2:$B$182,$A16) | C16: =COUNTIFS('Test cases'!$B$2:$B$182,$A16,'Test cases'!$H$2:$H$182,"Pass") | D16: =COUNTIFS('Test cases'!$B$2:$B$182,$A16,'Test cases'!$H$2:$H$182,"Fail") | E16: =COUNTIFS('Test cases'!$B$2:$B$182,$A16,'Test cases'!$H$2:$H$182,"Blocked") | F16: =COUNTIFS('Test cases'!$B$2:$B$182,$A16,'Test cases'!$H$2:$H$182,"Not run") | G16: =IF(B16=0,0,(C16+D16+E16)/B16) | H16: =COUNTIFS('Test cases'!$B$2:$B$182,$A16,'Test cases'!$C$2:$C$182,"P1") | I16: =COUNTIFS('Test cases'!$B$2:$B$182,$A16,'Test cases'!$C$2:$C$182,"P1",'Test cases'!$H$2:$H$182,"Pass")
... A21: End-to-end product scenarios (prepare a real document set for each) | B21: =COUNTIFS('Test cases'!$B$2:$B$182,$A21) | C21: =COUNTIFS('Test cases'!$B$2:$B$182,$A21,'Test cases'!$H$2:$H$182,"Pass") | D21: =COUNTIFS('Test cases'!$B$2:$B$182,$A21,'Test cases'!$H$2:$H$182,"Fail") | E21: =COUNTIFS('Test cases'!$B$2:$B$182,$A21,'Test cases'!$H$2:$H$182,"Blocked") | F21: =COUNTIFS('Test cases'!$B$2:$B$182,$A21,'Test cases'!$H$2:$H$182,"Not run") | G21: =IF(B21=0,0,(C21+D21+E21)/B21) | H21: =COUNTIFS('Test cases'!$B$2:$B$182,$A21,'Test cases'!$C$2:$C$182,"P1") | I21: =COUNTIFS('Test cases'!$B$2:$B$182,$A21,'Test cases'!$C$2:$C$182,"P1",'Test cases'!$H$2:$H$182,"Pass")
A22: All areas | B22: =SUM(B5:B21) | C22: =SUM(C5:C21) | D22: =SUM(D5:D21) | E22: =SUM(E5:E21) | F22: =SUM(F5:F21) | G22: =IF(B22=0,0,(C22+D22+E22)/B22) | H22: =SUM(H5:H21) | I22: =SUM(I5:I21)
A24: Release gate suggestion: every P1 case passed (column I equals column H) and no Fail left open.

Sheet Test cases
A1: ID | B1: Area | C1: Priority | D1: Scenario | E1: Documents / data needed | F1: Steps | G1: Expected result | H1: Result | I1: Tester notes (what you saw) | J1: Bug / fix reference | K1: Date tested
A2: ACC-01 | B2: Accounts & companies | C2: P1 | D2: Sign in with Google | E2: A Google account | F2: Open the live site > Sign in > Continue with Google. | G2: You land on the dashboard. The banner shows Sign out instead of Sign in. | H2: Not run
A3: ACC-02 | B3: Accounts & companies | C3: P2 | D3: Sign in with Microsoft | E3: A Microsoft account | F3: Sign in > Continue with Microsoft. | G3: You land on the dashboard with your own (empty or existing) company list. | H3: Not run
A4: ACC-03 | B4: Accounts & companies | C4: P2 | D4: Email sign-up, sign-in and password reset | E4: A fresh email address | F4: Sign up with email and password; sign out; sign in; use Forgot password and complete the reset. | G4: Each step works. The reset link opens the reset page and the new password signs you in. | H4: Not run
A5: ACC-04 | B5: Accounts & companies | C5: P1 | D5: Protected pages need a login | E5: None | F5: Sign out. Open /app and a product link directly. | G5: You are sent to the login page. No product data is shown. | H5: Not run
A6: ACC-05 | B6: Accounts & companies | C6: P1 | D6: First login creates a company | E6: None | F6: Sign in with a brand new account. | G6: You are asked to create a company (name required). After creating it you see an empty product table. | H6: Not run
A7: ACC-06 | B7: Accounts & companies | C7: P2 | D7: Several companies and switching | E7: Two companies | F7: Add another company. Create a product in each. Switch between them. | G7: Each company shows only its own products. The choice is remembered after a refresh. | H7: Not run
A8: ACC-07 | B8: Accounts & companies | C8: P3 | D8: Session expired during extraction | E8: A product with documents | F8: Sign out in a second tab, then press Extract with AI in the first. | G8: A clear 'session expired, sign in again' message, not a crash. | H8: Not run
A9: PRD-01 | B9: Product creation & documents | C9: P1 | D9: New product is created instantly | E9: None | F9: Press + New product. | G9: No name box. The product page opens at once, titled 'New product', with the three upload sections and a hint to upload then extract. | H9: Not run
A10: PRD-02 | B10: Product creation & documents | C10: P1 | D10: Upload each document type | E10: Formula PDF, certificate PDF, label image | F10: Upload one file in each of the three sections. | G10: Each file appears in its own section with a Remove link. Extract with AI becomes enabled. | H10: Not run
A11: PRD-03 | B11: Product creation & documents | C11: P2 | D11: Label as photo (JPG / PNG / HEIC from phone) | E11: A phone photo of a label | F11: Upload it as label artwork. | G11: It uploads and later extracts. If HEIC is not supported you get a clear message, not a silent failure. | H11: Not run
A12: PRD-04 | B12: Product creation & documents | C12: P2 | D12: File over 15 MB | E12: A PDF over 15 MB | F12: Try to upload it. | G12: Rejected with 'over 15MB' message. Nothing is stored. | H12: Not run
A13: PRD-05 | B13: Product creation & documents | C13: P2 | D13: Unsupported file types | E13: A .docx, .xlsx and .txt file | F13: Try to upload each (use the file picker 'All files' option if needed). | G13: They are refused or ignored with a clear message. The other documents are unaffected. | H13: Not run
... A182: E2E-13 | B182: End-to-end product scenarios (prepare a real document set for each) | C182: P3 | D182: E2E-M: Hotel amenity / home fragrance | E182: Documents for one of each | F182: Same flow. | G182: Sub-category 'Other' where Montaji defines it. | H182: Not run

Sheet Document pack
A1: Set | B1: Real documents to prepare | C1: What it lets us test | D1: Prepared? | E1: Folder / notes
A2: DOC-01 | B2: Imported cosmetic, 1 variant, formula with %, FSC, label (Real1 style) | C2: The standard happy path | D2: No
A3: DOC-02 | B3: UAE-made fragrance with matching composition certificate and GMP | C3: UAE branch, GMP, fragrances | D3: No
A4: DOC-03 | B4: Makeup with 2-3 shades, one barcode each, label photo of every shade | C4: Multi-variant fill, shade codes | D4: No
A5: DOC-04 | B5: Product with named shades (not numbers) | C5: Shade text kept as written | D5: No
A6: DOC-05 | B6: Product in 3 scents or flavours | C6: Scent/flavour variants | D6: No
A7: DOC-06 | B7: Product in 2 sizes with separate barcodes | C7: Multi-size variants, units | D7: No
A8: DOC-07 | B8: Formula as a scanned/photographed document | C8: Vision accuracy | D8: No
A9: DOC-08 | B9: Label as a phone photo, slightly tilted | C9: Image quality tolerance | D9: No
A10: DOC-09 | B10: Bilingual Arabic/English label | C10: Arabic handling | D10: No
A11: DOC-10 | B11: Label only (no formula, no certificate) | C11: Missing percentages, missing certificate warning | D11: No
A12: DOC-11 | B12: Formula with '<' values, CAS numbers and very small percentages (Real3 style) | C12: Percentage formats | D12: No
A13: DOC-12 | B13: Formula with 60+ ingredients, and one with 120+ | C13: Long lists and the 113 limit | D13: No
... A21: DOC-20 | B21: A damaged / password-protected PDF and a 16 MB file | C21: Error handling | D21: No

Sheet Data audit
A1: Field-by-field audit: RegPilot vs Montaji
A2: Fill one block per product after a run. Copy a block for more products. Variants: add the variant number to the field name.
A4: Product | B4: Step | C4: Field | D4: What to compare | E4: RegPilot value | F4: Montaji value | G4: Match? | H4: Notes
A5: Product A | B5: Step 2 | C5: Country of origin | D5: Same country, spelled as Montaji lists it
A6: Product A | B6: Step 2 | C6: Product name | D6: Identical text
A7: Product A | B7: Step 2 | C7: Group | D7: Same as RegPilot
A8: Product A | B8: Step 2 | C8: Category | D8: Same as RegPilot
A9: Product A | B9: Step 2 | C9: Sub-category | D9: Same as RegPilot
A10: Product A | B10: Step 2 | C10: Brand | D10: Same text
A11: Product A | B11: Step 3 | C11: Certificate file | D11: Right file in the right section (Free Sale or GMP)
A12: Product A | B12: Step 4 | C12: Barcode (each variant) | D12: Digit by digit
A13: Product A | B13: Step 4 | C13: Colour / shade (each variant) | D13: Manufacturer's own code or name
A14: Product A | B14: Step 4 | C14: Scent / flavour (each variant) | D14: Manufacturer's own name or NA
A15: Product A | B15: Step 4 | C15: Size / volume (each variant) | D15: Number (Montaji may show two decimals)
A16: Product A | B16: Step 4 | C16: Unit (each variant) | D16: Same unit
... A27: Product A | B27: Step 4 | C27: Save and Validate result | D27: Passed / the message shown
A30: Product | B30: Step | C30: Field | D30: What to compare | E30: RegPilot value | F30: Montaji value | G30: Match? | H30: Notes
A31: Product B | B31: Step 2 | C31: Country of origin | D31: Same country, spelled as Montaji lists it
A32: Product B | B32: Step 2 | C32: Product name | D32: Identical text
A33: Product B | B33: Step 2 | C33: Group | D33: Same as RegPilot
A34: Product B | B34: Step 2 | C34: Category | D34: Same as RegPilot
A35: Product B | B35: Step 2 | C35: Sub-category | D35: Same as RegPilot
A36: Product B | B36: Step 2 | C36: Brand | D36: Same text
A37: Product B | B37: Step 3 | C37: Certificate file | D37: Right file in the right section (Free Sale or GMP)
A38: Product B | B38: Step 4 | C38: Barcode (each variant) | D38: Digit by digit
A39: Product B | B39: Step 4 | C39: Colour / shade (each variant) | D39: Manufacturer's own code or name
A40: Product B | B40: Step 4 | C40: Scent / flavour (each variant) | D40: Manufacturer's own name or NA
A41: Product B | B41: Step 4 | C41: Size / volume (each variant) | D41: Number (Montaji may show two decimals)
A42: Product B | B42: Step 4 | C42: Unit (each variant) | D42: Same unit
... A53: Product B | B53: Step 4 | C53: Save and Validate result | D53: Passed / the message shown
A56: Product | B56: Step | C56: Field | D56: What to compare | E56: RegPilot value | F56: Montaji value | G56: Match? | H56: Notes
A57: Product C | B57: Step 2 | C57: Country of origin | D57: Same country, spelled as Montaji lists it
A58: Product C | B58: Step 2 | C58: Product name | D58: Identical text
A59: Product C | B59: Step 2 | C59: Group | D59: Same as RegPilot
A60: Product C | B60: Step 2 | C60: Category | D60: Same as RegPilot
A61: Product C | B61: Step 2 | C61: Sub-category | D61: Same as RegPilot
A62: Product C | B62: Step 2 | C62: Brand | D62: Same text
A63: Product C | B63: Step 3 | C63: Certificate file | D63: Right file in the right section (Free Sale or GMP)
A64: Product C | B64: Step 4 | C64: Barcode (each variant) | D64: Digit by digit
A65: Product C | B65: Step 4 | C65: Colour / shade (each variant) | D65: Manufacturer's own code or name
...

Sheet Known limits
A1: Topic | B1: What is known
A2: Detergents, Biocides, Health Supplements | B2: Taxonomy not built; you will send a master sheet. Until then classification is manual for these groups.
A3: Product Image upload | B3: Not collected or uploaded (optional on Montaji, planned for later).
A4: Laboratory Test Report | B4: Ignored on purpose.
A5: GMP certificate presence | B5: Nothing warns when a UAE product has no GMP certificate.
A6: Certificate validity dates | B6: Expiry of a certificate is not checked.
A7: 'Other' ingredient names | B7: Whether Montaji swaps ***Other*** for master-list names after validation is not yet confirmed.
A8: Ingredients without percentage | B8: Montaji's import rejects them, so they are always left for you.
A9: Existing product base | B9: Choosing an existing base on Step 2 is not supported; the extension creates a new one.
A10: Running Fill twice | B10: Behaviour on an already filled variant/ingredients is under test (see S4 and ING cases).
A11: After an extension reload | B11: Both the RegPilot tab and the Montaji tab must be refreshed.
A12: Unsaved edits | B12: Leaving the review form with unsaved edits has no warning (to be confirmed in REV tests).
... A15: Sequence numbers | B15: Number = highest existing + 1, so a deleted newest product's number can be reused.
